## 异常
- 异常是执行程序时发生的运行时错误。因此，我们的系统可能会挂起或发生某些事情。
- 检测错误条件的代码称为引发异常，处理错误的代码称为捕获异常。
- System.Exception:
  - C# 中的异常是一个对象，它封装了有关所发生错误的各种信息，例如异常点的堆栈跟踪和描述性错误消息。

## throw 抛出异常
```csharp
throw new xxException(...);
```
## 异常处理的代码定义
- try catch
- try catch finally
- try finally
```csharp
try{
   // 可能抛出异常的代码
   // catch 务必写好异常类型
}catch (ExceptionType1 ex1){
   // 异常类型1的处理逻辑
}finally{
   // 无论是否发生异常都会执行的代码，但是若是try中异常错误导致中断，则不执行
}
```
- 示例
```csharp
using System;

// 抛出异常
namespace Throw2 {
    public class NumberGenerator {
        int[] numbers = { 2, 4, 6, 8, 10, 12, 14, 16, 18, 20 };

        public int GetNumber(int index) {
            if (index < 0 || index >= numbers.Length) {
                throw new IndexOutOfRangeException();
            }

            return numbers[index];
        }
    }
}
// 具体示例,异常处理
public class Example {
    public static void Main() {
        var gen = new NumberGenerator();
        int index = 10;
        try {
            int value = gen.GetNumber(index);
            Console.WriteLine($"Retrieved {value}");
        } catch (IndexOutOfRangeException e) {
            Console.WriteLine($"{e.GetType().Name}: {index} is outside the bounds of the array");
        }
    }
}
// 输出结果: IndexOutOfRangeException: 10 is outside the bounds of the array
### 多次捕获
```csharp
using System;
using System.IO;

// catch的 异常变量名可以省略
class ExceptionTest {
    public static void Main() {
        try {
            string fileContents = new StreamReader(@"log.txt").ReadToEnd();
            Console.Write(fileContents);
        } catch (UnauthorizedAccessException e) // Access problems
        {
            Console.WriteLine(e.Message);
        } catch (FileNotFoundException e) // File does not exist
        {
            Console.WriteLine(e.Message);
        } catch (IOException e) // Some other IO problem.
        {
            Console.WriteLine(e.Message);
        }
    }
}
```
#### try
- try,只能初始化在try内部声明的变量, 若初始化外部声明的变量,则catch 会报错

#### finally未必一定执行
- 1. 在try块中调用了Environment.FailFast方法并且在应用程序域中没有注册任何异常处理程序；
- 2. 计算机关闭或意外崩溃时，finally块不会执行。
#### 除以0异常捕获
- ArithmeticException
### 重新引发异常
- throw 也可以用于 catch 块，以重新引发在 catch 块中处理的异常。在这种情况下，throw 不采用异常操作数。 当方法将参数从调用方传递给其他库方法时，这是最有用的，库方法引发的异常必须传递给调用方。
- 

## 系统异常
```md
System.IO.IOException	            处理 I/O 错误。
System.IndexOutOfRangeException	    处理当方法指向超出范围的数组索引时生成的错误。
System.ArrayTypeMismatchException	处理当数组类型不匹配时生成的错误。
System.NullReferenceException	    处理当依从一个空对象时生成的错误。
System.DivideByZeroException	    处理当除以零时生成的错误。
System.InvalidCastException	        处理在类型转换期间生成的错误。
System.OutOfMemoryException	        处理空闲内存不足生成的错误。
System.StackOverflowException	    处理栈溢出生成的错误。
```

### PS
```csharp
// 异常按从最具体到最不具体的顺序捕获。
// 例如，尝试访问不存在的文件， 将按以下顺序查找异常处理程序：
FileNotFoundException
IOException（基类FileNotFoundException)
SystemException（基类IOException)
Exception（基类SystemException)
```